Workbook
Name bbg_id: 'Bonds Universe'!#REF!
Name bbg_id: '[1]Reference Portfolio'!$E$5:$E$117
Name data: '[1]Reference Portfolio'!$C$5:$AE$117
Name er: 'Bonds Universe'!#REF!
Name F: '[2]Summary Sheet'!$A$3
Name g: '[3]Summary Sheet'!$A$3
Name GIFDATE: '[4]GIF Summary '!$B$1
Name GIFReportDate: '[5]Summary Sheet'!$A$3
Name GIFSHEETNEWDATE: [6]SUMMARY!$D$5
Name header: '[1]Reference Portfolio'!$C$4:$AE$4
Name month: '[7]Summary Sheet'!$G$3
Name New_GIF_Date: '[4]GIF Summary '!$I$1
Name ny: 'Bonds Universe'!#REF!
Name Previous_Month: '[4]GIF Summary '!$O$2
Name Previous_Year: '[4]GIF Summary '!$N$2
Name reportdate: '[4]Summary - Liabilities'!$A$2
Name s_header: '[8]2015 HP'!$C$17:$HU$17
Name sankore_id: 'Bonds Universe'!#REF!
Name solver_adj: 'Eurobond Trade Tracker'!#REF!
Name solver_adj: 'NGN Domestic Trade Tracker'!#REF!
Name solver_cvg: 0.0001
Name solver_cvg: 0.0001
Name solver_drv: 1
Name solver_drv: 1
Name solver_eng: 1
Name solver_eng: 1
Name solver_est: 1
Name solver_est: 1
Name solver_itr: 2147483647
Name solver_itr: 2147483647
Name solver_mip: 2147483647
Name solver_mip: 2147483647
Name solver_mni: 30
Name solver_mni: 30
Name solver_mrt: 0.075
Name solver_mrt: 0.075
Name solver_msl: 2
Name solver_msl: 2
Name solver_neg: 2
Name solver_neg: 2
Name solver_nod: 2147483647
Name solver_nod: 2147483647
Name solver_num: 0
Name solver_num: 0
Name solver_nwt: 1
Name solver_nwt: 1
Name solver_opt: 'Eurobond Trade Tracker'!#REF!
Name solver_opt: 'NGN Domestic Trade Tracker'!#REF!
Name solver_pre: 0.000001
Name solver_pre: 0.000001
Name solver_rbv: 1
Name solver_rbv: 1
Name solver_rlx: 2
Name solver_rlx: 2
Name solver_rsd: 0
Name solver_rsd: 0
Name solver_scl: 1
Name solver_scl: 1
Name solver_sho: 2
Name solver_sho: 2

Sheet Prev. Dashboard
B4: Average Gap | F4: Average Gap on Transactions | I4: Average Gap Per Trader | M4: Average Gap Per CP
B5: Month | C5: Per Month | D5: YTD
B6: 43861 | F6: Buy | G6: =AVERAGEIF('Eurobond Trade Tracker'!$F:$F,'Prev. Dashboard'!F6,'Eurobond Trade Tracker'!#REF!) -> #ERROR! | I6: Kamil | J6: Buy | K6: =AVERAGEIFS('Eurobond Trade Tracker'!#REF!,'Eurobond Trade Tracker'!$E:$E,'Prev. Dashboard'!$I$6,'Eurobond Trade Tracker'!$F:$F,'Prev. Dashboard'!J6) -> #ERROR!
B7: =EOMONTH(B6,1) -> 43890 | F7: Sell | G7: =AVERAGEIF('Eurobond Trade Tracker'!$F:$F,'Prev. Dashboard'!F7,'Eurobond Trade Tracker'!#REF!) -> #ERROR! | J7: Sell | K7: =AVERAGEIFS('Eurobond Trade Tracker'!#REF!,'Eurobond Trade Tracker'!$E:$E,'Prev. Dashboard'!$I$6,'Eurobond Trade Tracker'!$F:$F,'Prev. Dashboard'!J7) -> #ERROR!
B8: =EOMONTH(B7,1) -> 43921 | J8: Total | K8: =AVERAGEIF('Eurobond Trade Tracker'!E:E,'Prev. Dashboard'!I6,'Eurobond Trade Tracker'!#REF!) -> #ERROR!
B9: =EOMONTH(B8,1) -> 43951 | I9: Kingsley | J9: Buy | K9: =AVERAGEIFS('Eurobond Trade Tracker'!#REF!,'Eurobond Trade Tracker'!$E:$E,'Prev. Dashboard'!$I$9,'Eurobond Trade Tracker'!$F:$F,'Prev. Dashboard'!J9) -> #ERROR!
B10: =EOMONTH(B9,1) -> 43982 | J10: Sell | K10: =AVERAGEIFS('Eurobond Trade Tracker'!#REF!,'Eurobond Trade Tracker'!$E:$E,'Prev. Dashboard'!$I$9,'Eurobond Trade Tracker'!$F:$F,'Prev. Dashboard'!J10) -> #ERROR!
B11: =EOMONTH(B10,1) -> 44012 | J11: Total | K11: =AVERAGEIF('Eurobond Trade Tracker'!E:E,'Prev. Dashboard'!I9,'Eurobond Trade Tracker'!#REF!) -> #ERROR!
B12: =EOMONTH(B11,1) -> 44043 | I12: TOTAL | K12: =AVERAGE('Eurobond Trade Tracker'!#REF!) -> #ERROR!
B13: =EOMONTH(B12,1) -> 44074
B14: =EOMONTH(B13,1) -> 44104
B15: =EOMONTH(B14,1) -> 44135
B16: =EOMONTH(B15,1) -> 44165
B17: =EOMONTH(B16,1) -> 44196
B20: CP
B21: Comercio/Access
B22: Comercio/FBN Merchant
B23: Comercio/Stanbic
B24: Commercio
B25: FBN Bank (UK)
B26: FBN Market
B27: FBN UK
B28: First Bank Merchant
B29: Aztran/Globus bank
B30: Coronation Merchant Bank
B31: First Bank UK
... B62: Aztran/Providus

Sheet Dashboard
B3: Average GAP per Trader and Transaction
B4: Trader | C4: Buy | D4: Sell | E4: Total
B5: Rasheed
B6: Adedayo
B7: Total
B10: Average GAP per month
B11: Month | C11: Per month | D11: YTD
B12: 44227
B13: =EOMONTH(B12,1) -> 44255
B14: =EOMONTH(B13,1) -> 44286
B15: =EOMONTH(B14,1) -> 44316
B16: =EOMONTH(B15,1) -> 44347
B17: =EOMONTH(B16,1) -> 44377
B18: =EOMONTH(B17,1) -> 44408
B19: =EOMONTH(B18,1) -> 44439
B20: =EOMONTH(B19,1) -> 44469
B21: =EOMONTH(B20,1) -> 44500
B22: =EOMONTH(B21,1) -> 44530
B23: =EOMONTH(B22,1) -> 44561
B26: Average GAP per Counterparty
B27: Counterparty | C27: No of trades YTD | D27: Average GAP
B28: FBN UK
B29: FSDH
B30: Parthian
B31: Parthian Partners/UBA
B32: Parthian/Access Bank
B33: Parthian/UBA Custody
B34: Rencap
B35: Stanbic Nominees
B36: Zedcap/UBA Custody
B37: Zedcap/UBA GIS
B38: Zedcrest Capital/UBA
B39: Zenith
... B47: Chapelhill/FSDH

Sheet Eurobond Trade Tracker
E1: 0.07625 | F1: 828000 | G1: =#REF!*100/#REF! -> #REF! | M1: Modified | N1: Actual | O1: =TODAY()-40 -> 46227 | P1: =COUPNCD(O1,#REF!,2,0) -> #REF! | S1: 794774
H2: =COUPNCD(#REF!,#REF!,2,0) -> #REF! | I2: =(#REF!*#REF!)/2 -> #REF! | K2: 46532 | L2: Angola 2028 | M2: 47102 | N2: 46882 | Q2: =(#REF!*#REF!)/2 -> #REF! | U2: Sell | V2: PR004
J3: =COUNTA(#REF!) -> 1 | L3: Ghana 2032 | M3: 48330 | N3: 48299 | O3: 31567.5 | U3: Buy | V3: Bid code
L4: Ghana 2027 | M4: 46533 | N4: 46472
A6: S/N | B6: CP | C6: Settlement Bank | D6: Portfolio | E6: Trader | F6: Direction | G6: Name of Asset | H6: Coupon Rate | I6: Maturity Date | J6: Trade Date | K6: Settlement Date | L6: Ytm | M6: Price | N6: Face Value | O6: Consideration | P6: Principal | Q6: Accrued Interest | R6: Consideration | S6: ISIN | T6: Status | U6: Bloomberg Yield
B7: Access bank | C7: Stanbic | D7: GIF$ | E7: Victor | F7: Sell | G7: NGERIA 7.696 02/23/38 | H7: =IFERROR(VLOOKUP($G7,'Bonds Universe'!$D:$H,2,FALSE), "") -> 0.07696 | I7: =IFERROR(VLOOKUP($G7,'Bonds Universe'!$D:$H,3,FALSE), "") -> 50459 | J7: 45554 | K7: 45555 | L7: =IFERROR(YIELD(K7,I7,H7,M7,100,2,0),"") -> 0.1030339 | M7: 81.25 | N7: 400000 | O7: =IFERROR((N7*M7/100)+ACCRINT(COUPPCD(K7,I7,2,0),COUPNCD(K7,I7,2,0),K7,H7,N7,2,0),N7*M7/100) -> 327308.8 | P7: =N7*M7/100 -> 325000 | Q7: =IFERROR(ACCRINT(COUPPCD(K7,I7,2,0),COUPNCD(K7,I7,2,0),K7,H7,N7,2,0),"") -> 2308.8
B8: Rencap | C8: Mauritius | D8: SADF$ | E8: Victor | F8: Buy | G8: ETI 10.125% 10/15/2029 | H8: 0.10125 | I8: 47406 | J8: 45572 | K8: 45580 | L8: =IFERROR(YIELD(K8,I8,H8,M8,100,2,0),"") -> 0.10374872 | M8: 99.044 | N8: 4200000 | O8: =IFERROR((N8*M8/100)+ACCRINT(COUPPCD(K8,I8,2,0),COUPNCD(K8,I8,2,0),K8,H8,N8,2,0),N8*M8/100) -> 4159848 | P8: =N8*M8/100 -> 4159848 | Q8: =IFERROR(ACCRINT(COUPPCD(K8,I8,2,0),COUPNCD(K8,I8,2,0),K8,H8,N8,2,0),"") -> 0
B9: Access bank | C9: Mauritius | D9: SADF$ | E9: Dapo | F9: Sell | G9: SEPLAT 7.75 01/04/26 | H9: =IFERROR(VLOOKUP($G9,'Bonds Universe'!$D:$H,2,FALSE), "") -> 0.0775 | I9: =IFERROR(VLOOKUP($G9,'Bonds Universe'!$D:$H,3,FALSE), "") -> 46113 | J9: 45573 | K9: 45575 | L9: =IFERROR(YIELD(K9,I9,H9,M9,100,2,0),"") -> 0.080036529 | M9: 99.65 | N9: 2000000 | O9: =IFERROR((N9*M9/100)+ACCRINT(COUPPCD(K9,I9,2,0),COUPNCD(K9,I9,2,0),K9,H9,N9,2,0),N9*M9/100) -> 1996875 | P9: =N9*M9/100 -> 1993000 | Q9: =IFERROR(ACCRINT(COUPPCD(K9,I9,2,0),COUPNCD(K9,I9,2,0),K9,H9,N9,2,0),"") -> 3875
B10: Access bank | C10: Mauritius | D10: SADF$ | E10: Dapo | F10: Sell | G10: SEPLAT 7.75 01/04/26 | H10: =IFERROR(VLOOKUP($G10,'Bonds Universe'!$D:$H,2,FALSE), "") -> 0.0775 | I10: =IFERROR(VLOOKUP($G10,'Bonds Universe'!$D:$H,3,FALSE), "") -> 46113 | J10: 45574 | K10: 45576 | L10: =IFERROR(YIELD(K10,I10,H10,M10,100,2,0),"") -> 0.080405929 | M10: 99.6 | N10: 3000000 | O10: =IFERROR((N10*M10/100)+ACCRINT(COUPPCD(K10,I10,2,0),COUPNCD(K10,I10,2,0),K10,H10,N10,2,0),N10*M10/100) -> 2994458.3 | P10: =N10*M10/100 -> 2988000 | Q10: =IFERROR(ACCRINT(COUPPCD(K10,I10,2,0),COUPNCD(K10,I10,2,0),K10,H10,N10,2,0),"") -> 6458.3333
B11: Access bank | C11: Mauritius | D11: SADF$ | E11: Dapo | F11: Sell | G11: SEPLAT 7.75 01/04/26 | H11: =IFERROR(VLOOKUP($G11,'Bonds Universe'!$D:$H,2,FALSE), "") -> 0.0775 | I11: =IFERROR(VLOOKUP($G11,'Bonds Universe'!$D:$H,3,FALSE), "") -> 46113 | J11: 45575 | K11: 45581 | L11: =IFERROR(YIELD(K11,I11,H11,M11,100,2,0),"") -> 0.079677092 | M11: 99.7 | N11: 1280000 | O11: =IFERROR((N11*M11/100)+ACCRINT(COUPPCD(K11,I11,2,0),COUPNCD(K11,I11,2,0),K11,H11,N11,2,0),N11*M11/100) -> 1280293.3 | P11: =N11*M11/100 -> 1276160 | Q11: =IFERROR(ACCRINT(COUPPCD(K11,I11,2,0),COUPNCD(K11,I11,2,0),K11,H11,N11,2,0),"") -> 4133.3333
B12: Access bank | C12: Stanbic | D12: GIF$ | E12: Dapo | F12: Sell | G12: SEPLAT 7.75 01/04/26 | H12: =IFERROR(VLOOKUP($G12,'Bonds Universe'!$D:$H,2,FALSE), "") -> 0.0775 | I12: =IFERROR(VLOOKUP($G12,'Bonds Universe'!$D:$H,3,FALSE), "") -> 46113 | J12: 45575 | K12: 45581 | L12: =IFERROR(YIELD(K12,I12,H12,M12,100,2,0),"") -> 0.079677092 | M12: 99.7 | N12: 450000 | O12: =IFERROR((N12*M12/100)+ACCRINT(COUPPCD(K12,I12,2,0),COUPNCD(K12,I12,2,0),K12,H12,N12,2,0),N12*M12/100) -> 450103.12 | P12: =N12*M12/100 -> 448650 | Q12: =IFERROR(ACCRINT(COUPPCD(K12,I12,2,0),COUPNCD(K12,I12,2,0),K12,H12,N12,2,0),"") -> 1453.125
A13: SMA Mr Ajene | B13: Access bank | C13: Stanbic | D13: GIF$ | E13: Victor | F13: Buy | G13: ANGOL 8.75 04/14/2032 | H13: =IFERROR(VLOOKUP($G13,'Bonds Universe'!$D:$H,2,FALSE), "") -> 0.0875 | I13: =IFERROR(VLOOKUP($G13,'Bonds Universe'!$D:$H,3,FALSE), "") -> 48318 | J13: 45581 | K13: 45583 | L13: =IFERROR(YIELD(K13,I13,H13,M13,100,2,0),"") -> 0.10620442 | M13: 90.5 | N13: 200000 | O13: =IFERROR((N13*M13/100)+ACCRINT(COUPPCD(K13,I13,2,0),COUPNCD(K13,I13,2,0),K13,H13,N13,2,0),N13*M13/100) -> 181194.44 | P13: =N13*M13/100 -> 181000 | Q13: =IFERROR(ACCRINT(COUPPCD(K13,I13,2,0),COUPNCD(K13,I13,2,0),K13,H13,N13,2,0),"") -> 194.44444
B14: BCP Securities | C14: Mauritius | D14: SADF$ | E14: Dapo | F14: Buy | G14: EGYPT 8 7/8 05/29/50 | H14: =IFERROR(VLOOKUP($G14,'Bonds Universe'!$D:$H,2,FALSE), "") -> 0.08875 | I14: =IFERROR(VLOOKUP($G14,'Bonds Universe'!$D:$H,3,FALSE), "") -> 54937 | J14: 45586 | K14: 45588 | L14: =IFERROR(YIELD(K14,I14,H14,M14,100,2,0),"") -> 0.10891836 | M14: 82.69 | N14: 1000000 | O14: =IFERROR((N14*M14/100)+ACCRINT(COUPPCD(K14,I14,2,0),COUPNCD(K14,I14,2,0),K14,H14,N14,2,0),N14*M14/100) -> 862400 | P14: =N14*M14/100 -> 826900 | Q14: =IFERROR(ACCRINT(COUPPCD(K14,I14,2,0),COUPNCD(K14,I14,2,0),K14,H14,N14,2,0),"") -> 35500
B15: Access bank | C15: Stanbic | D15: GIF$ | E15: Dapo | F15: Buy | G15: ANGOL 9 3/8 05/08/48 | H15: =IFERROR(VLOOKUP($G15,'Bonds Universe'!$D:$H,2,FALSE), "") -> 0.09375 | I15: =IFERROR(VLOOKUP($G15,'Bonds Universe'!$D:$H,3,FALSE), "") -> 54186 | J15: 45583 | K15: 45587 | L15: =IFERROR(YIELD(K15,I15,H15,M15,100,2,0),"") -> 0.11100067 | M15: 85.67 | N15: 600000 | O15: =IFERROR((N15*M15/100)+ACCRINT(COUPPCD(K15,I15,2,0),COUPNCD(K15,I15,2,0),K15,H15,N15,2,0),N15*M15/100) -> 539645 | P15: =N15*M15/100 -> 514020 | Q15: =IFERROR(ACCRINT(COUPPCD(K15,I15,2,0),COUPNCD(K15,I15,2,0),K15,H15,N15,2,0),"") -> 25625
B16: Access bank | C16: Mauritius | D16: SADF$ | E16: Dapo | F16: Buy | G16: ANGOL 9 3/8 05/08/48 | H16: =IFERROR(VLOOKUP($G16,'Bonds Universe'!$D:$H,2,FALSE), "") -> 0.09375 | I16: =IFERROR(VLOOKUP($G16,'Bonds Universe'!$D:$H,3,FALSE), "") -> 54186 | J16: 45586 | K16: 45588 | L16: =IFERROR(YIELD(K16,I16,H16,M16,100,2,0),"") -> 0.11109815 | M16: 85.6 | N16: 1700000 | O16: =IFERROR((N16*M16/100)+ACCRINT(COUPPCD(K16,I16,2,0),COUPNCD(K16,I16,2,0),K16,H16,N16,2,0),N16*M16/100) -> 1528246.9 | P16: =N16*M16/100 -> 1455200 | Q16: =IFERROR(ACCRINT(COUPPCD(K16,I16,2,0),COUPNCD(K16,I16,2,0),K16,H16,N16,2,0),"") -> 73046.875
B17: First Bank UK | C17: Mauritius | D17: SADF$ | E17: Dapo | F17: Buy | G17: ANGOL 9 1/8 11/26/49 | H17: =IFERROR(VLOOKUP($G17,'Bonds Universe'!$D:$H,2,FALSE), "") -> 0.09125 | I17: =IFERROR(VLOOKUP($G17,'Bonds Universe'!$D:$H,3,FALSE), "") -> 54753 | J17: 45593 | K17: 45595 | L17: =IFERROR(YIELD(K17,I17,H17,M17,100,2,0),"") -> 0.11048432 | M17: 83.75 | N17: 450000 | O17: =IFERROR((N17*M17/100)+ACCRINT(COUPPCD(K17,I17,2,0),COUPNCD(K17,I17,2,0),K17,H17,N17,2,0),N17*M17/100) -> 394440.62 | P17: =N17*M17/100 -> 376875 | Q17: =IFERROR(ACCRINT(COUPPCD(K17,I17,2,0),COUPNCD(K17,I17,2,0),K17,H17,N17,2,0),"") -> 17565.625
B18: Access bank | C18: Stanbic | D18: GIF$ | E18: Dapo | F18: Buy | G18: ANGOL 9 1/8 11/26/49 | H18: =IFERROR(VLOOKUP($G18,'Bonds Universe'!$D:$H,2,FALSE), "") -> 0.09125 | I18: =IFERROR(VLOOKUP($G18,'Bonds Universe'!$D:$H,3,FALSE), "") -> 54753 | J18: 45593 | K18: 45595 | L18: =IFERROR(YIELD(K18,I18,H18,M18,100,2,0),"") -> 0.1105533 | M18: 83.7 | N18: 600000 | O18: =IFERROR((N18*M18/100)+ACCRINT(COUPPCD(K18,I18,2,0),COUPNCD(K18,I18,2,0),K18,H18,N18,2,0),N18*M18/100) -> 525620.83 | P18: =N18*M18/100 -> 502200 | Q18: =IFERROR(ACCRINT(COUPPCD(K18,I18,2,0),COUPNCD(K18,I18,2,0),K18,H18,N18,2,0),"") -> 23420.833
B19: Access bank | C19: Stanbic | D19: GIF$ | E19: Dapo | F19: Buy | G19: ANGOL 9 1/8 11/26/49 | H19: =IFERROR(VLOOKUP($G19,'Bonds Universe'!$D:$H,2,FALSE), "") -> 0.09125 | I19: =IFERROR(VLOOKUP($G19,'Bonds Universe'!$D:$H,3,FALSE), "") -> 54753 | J19: 45593 | K19: 45595 | L19: =IFERROR(YIELD(K19,I19,H19,M19,100,2,0),"") -> 0.11020908 | M19: 83.95 | N19: 400000 | O19: =IFERROR((N19*M19/100)+ACCRINT(COUPPCD(K19,I19,2,0),COUPNCD(K19,I19,2,0),K19,H19,N19,2,0),N19*M19/100) -> 351413.89 | P19: =N19*M19/100 -> 335800 | Q19: =IFERROR(ACCRINT(COUPPCD(K19,I19,2,0),COUPNCD(K19,I19,2,0),K19,H19,N19,2,0),"") -> 15613.889
A20: SMA Woodlake | B20: Access bank | C20: Stanbic | D20: GIF$ | E20: Dapo | F20: Sell | G20: GHANA 5 07/03/29 | H20: 0.05 | I20: 47302 | J20: 45601 | K20: 45603 | L20: =IFERROR(YIELD(K20,I20,H20,M20,100,2,0),"") -> 0.089760798 | M20: 85.125 | N20: 411158 | O20: =IFERROR((N20*M20/100)+ACCRINT(COUPPCD(K20,I20,2,0),COUPNCD(K20,I20,2,0),K20,H20,N20,2,0),N20*M20/100) -> 357079.3 | P20: =N20*M20/100 -> 349998.25 | Q20: =IFERROR(ACCRINT(COUPPCD(K20,I20,2,0),COUPNCD(K20,I20,2,0),K20,H20,N20,2,0),"") -> 7081.0544
A21: SMA Woodlake | B21: Access bank | C21: Stanbic | D21: GIF$ | E21: Dapo | F21: Sell | G21: GHANA 5 07/03/35 | H21: 0.05 | I21: 49493 | J21: 45601 | K21: 45603 | L21: =IFERROR(YIELD(K21,I21,H21,M21,100,2,0),"") -> 0.097861083 | M21: 68.75 | N21: 591252 | O21: =IFERROR((N21*M21/100)+ACCRINT(COUPPCD(K21,I21,2,0),COUPNCD(K21,I21,2,0),K21,H21,N21,2,0),N21*M21/100) -> 416668.42 | P21: =N21*M21/100 -> 406485.75 | Q21: =IFERROR(ACCRINT(COUPPCD(K21,I21,2,0),COUPNCD(K21,I21,2,0),K21,H21,N21,2,0),"") -> 10182.673
A22: SMA Woodlake | B22: Access bank | C22: Stanbic | D22: GIF$ | E22: Dapo | F22: Sell | G22: GHANA 0 01/03/30 | H22: 0 | I22: 47486 | J22: 45601 | K22: 45603 | L22: =IFERROR(YIELD(K22,I22,H22,M22,100,2,0),"") -> 0.057920687 | M22: 74.5 | N22: 96188.35 | O22: 65690.78 | P22: 65690.78 | Q22: =IFERROR(ACCRINT(COUPPCD(K22,I22,2,0),COUPNCD(K22,I22,2,0),K22,H22,N22,2,0),"")
A23: Sankore & Woodlake | B23: Access bank | C23: Stanbic | D23: GIF$ | E23: Dapo | F23: Sell | G23: GHANA 0 07/03/26 | H23: 0 | I23: 46206 | J23: 45602 | K23: 45604 | L23: =IFERROR(YIELD(K23,I23,H23,M23,100,2,0),"") -> 0.054475304 | M23: 91.5 | N23: 75720 | O23: 55427.04 | P23: 55427.04 | Q23: =IFERROR(ACCRINT(COUPPCD(K23,I23,2,0),COUPNCD(K23,I23,2,0),K23,H23,N23,2,0),"")
A24: Sankore & Chidi | B24: Access bank | C24: Stanbic | D24: GIF$ | E24: Dapo | F24: Sell | G24: GHANA 5 07/03/29 | H24: 0.05 | I24: 47302 | J24: 45602 | K24: 45604 | L24: =IFERROR(YIELD(K24,I24,H24,M24,100,2,0),"") -> 0.090151008 | M24: 85 | N24: 78408 | O24: =IFERROR((N24*M24/100)+ACCRINT(COUPPCD(K24,I24,2,0),COUPNCD(K24,I24,2,0),K24,H24,N24,2,0),N24*M24/100) -> 68008.05 | P24: =N24*M24/100 -> 66646.8 | Q24: =IFERROR(ACCRINT(COUPPCD(K24,I24,2,0),COUPNCD(K24,I24,2,0),K24,H24,N24,2,0),"") -> 1361.25
A25: Sankore & Chidi | B25: Access bank | C25: Stanbic | D25: GIF$ | E25: Dapo | F25: Sell | G25: GHANA 5 07/03/35 | H25: 0.05 | I25: 49493 | J25: 45602 | K25: 45604 | L25: =IFERROR(YIELD(K25,I25,H25,M25,100,2,0),"") -> 0.097870472 | M25: 68.75 | N25: 112752 | O25: =IFERROR((N25*M25/100)+ACCRINT(COUPPCD(K25,I25,2,0),COUPNCD(K25,I25,2,0),K25,H25,N25,2,0),N25*M25/100) -> 79474.5 | P25: =N25*M25/100 -> 77517 | Q25: =IFERROR(ACCRINT(COUPPCD(K25,I25,2,0),COUPNCD(K25,I25,2,0),K25,H25,N25,2,0),"") -> 1957.5
A26: Sankore & Chidi | B26: BCP Securities | C26: Stanbic | D26: GIF$ | E26: Dapo | F26: Sell | G26: GHANA 0 01/03/30 | H26: 0 | I26: 47486 | J26: 45603 | K26: 45608 | L26: =IFERROR(YIELD(K26,I26,H26,M26,100,2,0),"") -> 0.055412587 | M26: 75.5 | N26: 24093 | O26: =IFERROR((N26*M26/100)+ACCRINT(COUPPCD(K26,I26,2,0),COUPNCD(K26,I26,2,0),K26,H26,N26,2,0),N26*M26/100)*0.9167 -> 16674.97 | P26: =N26*M26/100 -> 18190.215 | Q26: =IFERROR(ACCRINT(COUPPCD(K26,I26,2,0),COUPNCD(K26,I26,2,0),K26,H26,N26,2,0),"")
B27: Access bank | C27: Mauritius | D27: SADF$ | E27: Dapo | F27: Sell | G27: ETINL 8 3/4 06/17/31 | H27: =IFERROR(VLOOKUP($G27,'Bonds Universe'!$D:$H,2,FALSE), "") -> 0.0875 | I27: =IFERROR(VLOOKUP($G27,'Bonds Universe'!$D:$H,3,FALSE), "") -> 48016 | J27: 45616 | K27: 45618 | L27: =IFERROR(YIELD(K27,I27,H27,M27,100,2,0),"") -> 0.089522752 | M27: 99 | N27: 5654000 | O27: =IFERROR((N27*M27/100)+ACCRINT(COUPPCD(K27,I27,2,0),COUPNCD(K27,I27,2,0),K27,H27,N27,2,0),N27*M27/100) -> 5810466.6 | P27: =N27*M27/100 -> 5597460 | Q27: =IFERROR(ACCRINT(COUPPCD(K27,I27,2,0),COUPNCD(K27,I27,2,0),K27,H27,N27,2,0),"") -> 213006.6
B28: Access bank | C28: Mauritius | D28: SADF$ | E28: Dapo | F28: Buy | G28: EGYPT 8 1/2 01/31/47 | H28: =IFERROR(VLOOKUP($G28,'Bonds Universe'!$D:$H,2,FALSE), "") -> 0.085 | I28: =IFERROR(VLOOKUP($G28,'Bonds Universe'!$D:$H,3,FALSE), "") -> 53723 | J28: 45616 | K28: 45621 | L28: =IFERROR(YIELD(K28,I28,H28,M28,100,2,0),"") -> 0.11060411 | M28: 78.95 | N28: 5315000 | O28: =IFERROR((N28*M28/100)+ACCRINT(COUPPCD(K28,I28,2,0),COUPNCD(K28,I28,2,0),K28,H28,N28,2,0),N28*M28/100) -> 4340509.5 | P28: =N28*M28/100 -> 4196192.5 | Q28: =IFERROR(ACCRINT(COUPPCD(K28,I28,2,0),COUPNCD(K28,I28,2,0),K28,H28,N28,2,0),"") -> 144317.01
B29: Access bank | C29: Mauritius | D29: SADF$ | E29: Dapo | F29: Buy | G29: ANGOL 9 3/8 05/08/48 | H29: =IFERROR(VLOOKUP($G29,'Bonds Universe'!$D:$H,2,FALSE), "") -> 0.09375 | I29: =IFERROR(VLOOKUP($G29,'Bonds Universe'!$D:$H,3,FALSE), "") -> 54186 | J29: 45616 | K29: 45621 | L29: =IFERROR(YIELD(K29,I29,H29,M29,100,2,0),"") -> 0.11390667 | M29: 83.61 | N29: 1733000 | O29: 1521169.6 | P29: =N29*M29/100 -> 1448961.3 | Q29: =IFERROR(ACCRINT(COUPPCD(K29,I29,2,0),COUPNCD(K29,I29,2,0),K29,H29,N29,2,0),"") -> 7672.1354
B30: Access bank | C30: Stanbic | D30: GIF$ | E30: Dapo | F30: Buy | G30: ANGOL 9 3/8 05/08/48 | H30: =IFERROR(VLOOKUP($G30,'Bonds Universe'!$D:$H,2,FALSE), "") -> 0.09375 | I30: =IFERROR(VLOOKUP($G30,'Bonds Universe'!$D:$H,3,FALSE), "") -> 54186 | J30: 45616 | K30: 45621 | L30: =IFERROR(YIELD(K30,I30,H30,M30,100,2,0),"") -> 0.11390667 | M30: 83.61 | N30: 545000 | O30: 478382.83 | P30: =N30*M30/100 -> 455674.5 | Q30: =IFERROR(ACCRINT(COUPPCD(K30,I30,2,0),COUPNCD(K30,I30,2,0),K30,H30,N30,2,0),"") -> 2412.7604
B31: BCP Securities | C31: Stanbic | D31: GIF$ | E31: Dapo | F31: Buy | G31: ANGOL 9 3/8 05/08/48 | H31: =IFERROR(VLOOKUP($G31,'Bonds Universe'!$D:$H,2,FALSE), "") -> 0.09375 | I31: =IFERROR(VLOOKUP($G31,'Bonds Universe'!$D:$H,3,FALSE), "") -> 54186 | J31: 45625 | K31: 45629 | L31: =IFERROR(YIELD(K31,I31,H31,M31,100,2,0),"") -> 0.11334855 | M31: 84 | N31: 1135000 | O31: 1003056.2 | P31: =N31*M31/100 -> 953400 | Q31: =IFERROR(ACCRINT(COUPPCD(K31,I31,2,0),COUPNCD(K31,I31,2,0),K31,H31,N31,2,0),"") -> 7389.3229
B32: Access bank | C32: Mauritius | D32: SADF$ | E32: Dapo | F32: Sell | G32: ETINL 8 3/4 06/17/31 | H32: =IFERROR(VLOOKUP($G32,'Bonds Universe'!$D:$H,2,FALSE), "") -> 0.0875 | I32: =IFERROR(VLOOKUP($G32,'Bonds Universe'!$D:$H,3,FALSE), "") -> 48016 | J32: 45644 | K32: 45646 | L32: =IFERROR(YIELD(K32,I32,H32,M32,100,2,0),"") -> 0.089665404 | M32: 98.95 | N32: 750000 | O32: =IFERROR((N32*M32/100)+ACCRINT(COUPPCD(K32,I32,2,0),COUPNCD(K32,I32,2,0),K32,H32,N32,2,0),N32*M32/100) -> 742671.88 | P32: =N32*M32/100 -> 742125 | Q32: =IFERROR(ACCRINT(COUPPCD(K32,I32,2,0),COUPNCD(K32,I32,2,0),K32,H32,N32,2,0),"") -> 546.875
B33: Access bank | C33: Mauritius | D33: SADF$ | E33: Oise | F33: Sell | G33: NIGERIA 6.125 9/28/28 | H33: =IFERROR(VLOOKUP($G33,'Bonds Universe'!$D:$H,2,FALSE), "") -> 0.06125 | I33: =IFERROR(VLOOKUP($G33,'Bonds Universe'!$D:$H,3,FALSE), "") -> 47024 | J33: 45694 | K33: 45695 | L33: =IFERROR(YIELD(K33,I33,H33,M33,100,2,0),"") -> 0.087152931 | M33: 92.05 | N33: 4070000 | O33: =IFERROR((N33*M33/100)+ACCRINT(COUPPCD(K33,I33,2,0),COUPNCD(K33,I33,2,0),K33,H33,N33,2,0),N33*M33/100) -> 3835763 | P33: =N33*M33/100 -> 3746435 | Q33: =IFERROR(ACCRINT(COUPPCD(K33,I33,2,0),COUPNCD(K33,I33,2,0),K33,H33,N33,2,0),"") -> 89328.021
B34: Access bank | C34: Mauritius | D34: SADF$ | E34: Oise | F34: Sell | G34: ETI 10.125% 10/15/2029 | H34: 0.10125 | I34: 47406 | J34: 45694 | K34: 45695 | L34: =IFERROR(YIELD(K34,I34,H34,M34,100,2,0),"") -> 0.088196676 | M34: 104.9 | N34: 4200000 | O34: =IFERROR((N34*M34/100)+ACCRINT(COUPPCD(K34,I34,2,0),COUPNCD(K34,I34,2,0),K34,H34,N34,2,0),N34*M34/100) -> 4538100 | P34: =N34*M34/100 -> 4405800 | Q34: =IFERROR(ACCRINT(COUPPCD(K34,I34,2,0),COUPNCD(K34,I34,2,0),K34,H34,N34,2,0),"") -> 132300
B35: Access bank | C35: Mauritius | D35: SADF$ | E35: Oise | F35: Sell | G35: ETINL 8 3/4 06/17/31 | H35: =IFERROR(VLOOKUP($G35,'Bonds Universe'!$D:$H,2,FALSE), "") -> 0.0875 | I35: =IFERROR(VLOOKUP($G35,'Bonds Universe'!$D:$H,3,FALSE), "") -> 48016 | J35: 45695 | K35: 45699 | L35: =IFERROR(YIELD(K35,I35,H35,M35,100,2,0),"") -> 0.089082496 | M35: 99.225 | N35: 4095000 | O35: =IFERROR((N35*M35/100)+ACCRINT(COUPPCD(K35,I35,2,0),COUPNCD(K35,I35,2,0),K35,H35,N35,2,0),N35*M35/100) -> 4117010.6 | P35: =N35*M35/100 -> 4063263.8 | Q35: =IFERROR(ACCRINT(COUPPCD(K35,I35,2,0),COUPNCD(K35,I35,2,0),K35,H35,N35,2,0),"") -> 53746.875
A36: Ram Lokan | B36: FBN UK | C36: Stanbic | D36: SMA | E36: William | F36: Buy | G36: ECOBANK 7.125% 02/16/2026 | H36: 0.07125 | I36: 46069 | J36: 45699 | K36: 45701 | L36: =IFERROR(YIELD(K36,I36,H36,M36,100,2,0),"") -> 0.081770697 | M36: 99 | N36: 394000 | O36: =IFERROR((N36*M36/100)+ACCRINT(COUPPCD(K36,I36,2,0),COUPNCD(K36,I36,2,0),K36,H36,N36,2,0),N36*M36/100) -> 403862.31 | P36: =N36*M36/100 -> 390060 | Q36: =IFERROR(ACCRINT(COUPPCD(K36,I36,2,0),COUPNCD(K36,I36,2,0),K36,H36,N36,2,0),"") -> 13802.312
A37: Ram Lokan | B37: FBN UK | C37: Stanbic | D37: SMA | E37: William | F37: Sell | G37: ECOBANK 7.125% 02/16/2026 | H37: 0.07125 | I37: 46069 | J37: 45699 | K37: 45701 | L37: =IFERROR(YIELD(K37,I37,H37,M37,100,2,0),"") -> 0.081770697 | M37: 99 | N37: 200000 | O37: =IFERROR((N37*M37/100)+ACCRINT(COUPPCD(K37,I37,2,0),COUPNCD(K37,I37,2,0),K37,H37,N37,2,0),N37*M37/100) -> 205006.25 | P37: =N37*M37/100 -> 198000 | Q37: =IFERROR(ACCRINT(COUPPCD(K37,I37,2,0),COUPNCD(K37,I37,2,0),K37,H37,N37,2,0),"") -> 7006.25
B38: Access bank | C38: Stanbic | D38: GIF$ | E38: Oise | F38: Sell | G38: ANGOL 9 1/8 11/26/49 | H38: =IFERROR(VLOOKUP($G38,'Bonds Universe'!$D:$H,2,FALSE), "") -> 0.09125 | I38: =IFERROR(VLOOKUP($G38,'Bonds Universe'!$D:$H,3,FALSE), "") -> 54753 | J38: 45708 | K38: 45712 | L38: =IFERROR(YIELD(K38,I38,H38,M38,100,2,0),"") -> 0.11399256 | M38: 81.3 | N38: 1000000 | O38: =IFERROR((N38*M38/100)+ACCRINT(COUPPCD(K38,I38,2,0),COUPNCD(K38,I38,2,0),K38,H38,N38,2,0),N38*M38/100) -> 835305.56 | P38: =N38*M38/100 -> 813000 | Q38: =IFERROR(ACCRINT(COUPPCD(K38,I38,2,0),COUPNCD(K38,I38,2,0),K38,H38,N38,2,0),"") -> 22305.556
B39: FBN UK | C39: Stanbic | D39: GIF$ | E39: Oise | F39: Sell | G39: ANGOL 9 3/8 05/08/48 | H39: =IFERROR(VLOOKUP($G39,'Bonds Universe'!$D:$H,2,FALSE), "") -> 0.09375 | I39: =IFERROR(VLOOKUP($G39,'Bonds Universe'!$D:$H,3,FALSE), "") -> 54186 | J39: 45708 | K39: 45712 | L39: =IFERROR(YIELD(K39,I39,H39,M39,100,2,0),"") -> 0.11462903 | M39: 83.125 | N39: 2280000 | O39: 1936218.8 | P39: =N39*M39/100 -> 1895250 | Q39: =IFERROR(ACCRINT(COUPPCD(K39,I39,2,0),COUPNCD(K39,I39,2,0),K39,H39,N39,2,0),"") -> 62937.5
B40: FBN UK | C40: Stanbic | D40: GIF$ | E40: Oise | F40: Sell | G40: ACCESS 9 1/8 PERP | H40: =IFERROR(VLOOKUP($G40,'Bonds Universe'!$D:$H,2,FALSE), "") -> 0.09125 | I40: =IFERROR(VLOOKUP($G40,'Bonds Universe'!$D:$H,3,FALSE), "") -> 46210 | J40: 45708 | K40: 45712 | L40: =IFERROR(YIELD(K40,I40,H40,M40,100,2,0),"") -> 0.083232058 | M40: 101 | N40: 291000 | O40: =IFERROR((N40*M40/100)+ACCRINT(COUPPCD(K40,I40,2,0),COUPNCD(K40,I40,2,0),K40,H40,N40,2,0),N40*M40/100) -> 297376.74 | P40: =N40*M40/100 -> 293910 | Q40: =IFERROR(ACCRINT(COUPPCD(K40,I40,2,0),COUPNCD(K40,I40,2,0),K40,H40,N40,2,0),"") -> 3466.7396
B41: Access bank | C41: Mauritius | D41: SADF$ | E41: Oise | F41: Sell | G41: NGERIA 9.248 01/21/49 | H41: =IFERROR(VLOOKUP($G41,'Bonds Universe'!$D:$H,2,FALSE), "") -> 0.09248 | I41: =IFERROR(VLOOKUP($G41,'Bonds Universe'!$D:$H,3,FALSE), "") -> 54444 | J41: 45719 | K41: 45721 | L41: =IFERROR(YIELD(K41,I41,H41,M41,100,2,0),"") -> 0.098710526 | M41: 94.3 | N41: 260000 | O41: =IFERROR((N41*M41/100)+ACCRINT(COUPPCD(K41,I41,2,0),COUPNCD(K41,I41,2,0),K41,H41,N41,2,0),N41*M41/100) -> 248118.81 | P41: =N41*M41/100 -> 245180 | Q41: =IFERROR(ACCRINT(COUPPCD(K41,I41,2,0),COUPNCD(K41,I41,2,0),K41,H41,N41,2,0),"") -> 2938.8089
...

Sheet Ghana Domestic Trade Tracker
L1: =TODAY() -> 46267 | M1: 44196 | N1: 364 | O1: =N1/2 -> 182
A5: S/N | B5: CP | C5: Settlement Bank | D5: Portfolio | E5: Trader | F5: Direction | G5: Name of Asset | H5: ISIN | I5: Coupon Rate | J5: Issue Date | K5: Last Coupon date | L5: No of Days | M5: Maturity Date | N5: Trade Date | O5: Settlement Date | P5: Ytm | Q5: Price | R5: Face Value | S5: Principal | T5: Accrued Interest | U5: Settlement Cost | V5: CSD Cost | W5: Net Consideration Paid | X5: Settlement Cost | Z5: FX | AA5: Status
A6: 1 | B6: I.C Securities/Access Bank Ghana | C6: Mauritius | D6: SADF GHC | E6: Kamil | F6: Buy | G6: GOG-BD-16/01/23 20.75 | J6: 43850 | K6: =J6+$O$1 -> 44032 | L6: =O6-K6 -> 148 | N6: 44179 | O6: 44180 | P6: =IFERROR(YIELD(O6,M6,I6,Q6,100,2,0),"") | Q6: 102.839 | R6: 3587000 | S6: =R6*Q6/100 -> 3688834.9 | T6: =R6*I6*(L6/$N$1) -> 0 | U6: =S6+T6 -> 3688834.9 | V6: =U6*0.01% -> 368.88349 | W6: =IF(F6="Buy",U6+V6,U6-V6) -> 3689203.8 | X6: 3991477.8 | Y6: =X6-U6 -> 302642.84 | AA6: Settled
A7: 2 | B7: I.C Securities/Access Bank Ghana | C7: Mauritius | D7: SADF GHC | E7: Kamil | F7: Buy | G7: GOG-BD-06/03/23 20.75 | J7: 43899 | K7: =J7+$O$1 -> 44081 | L7: =O7-K7 -> 99 | N7: 44179 | O7: 44180 | P7: =IFERROR(YIELD(O7,M7,I7,Q7,100,2,0),"") | Q7: 103.216 | R7: 3628000 | S7: =R7*Q7/100 -> 3744676.5 | T7: =R7*I7*(L7/$N$1) -> 0 | U7: =S7+T7 -> 3744676.5 | V7: =U7*0.01% -> 374.46765 | W7: =IF(F7="Buy",U7+V7,U7-V7) -> 3745050.9 | X7: 3949427.9 | Y7: =X7-U7 -> 204751.4 | AA7: Settled
A8: 3 | B8: I.C Securities/Access Bank Ghana | C8: Mauritius | D8: SADF GHC | E8: Kamil | F8: Buy | G8: GOG-BD-27/11/23 19.25 | J8: 44165 | K8: =J8 -> 44165 | L8: =O8-K8 -> 17 | N8: 44180 | O8: 44182 | P8: =IFERROR(YIELD(O8,M8,I8,Q8,100,2,0),"") | Q8: 100.95 | R8: 3889000 | S8: =R8*Q8/100 -> 3925945.5 | T8: =R8*I8*(L8/$N$1) -> 0 | U8: =S8+T8 -> 3925945.5 | V8: =U8*0.01% -> 392.59455 | W8: =IF(F8="Buy",U8+V8,U8-V8) -> 3926338.1 | X8: 3960889.7 | Y8: =X8-U8 -> 34944.17 | AA8: Settled
A9: 1 | B9: I.C Securities/Access Bank Ghana | C9: Mauritius | D9: SADF GHC | E9: Rasheed | F9: Buy | G9: GOG-BD 13/10/25 19.85 | I9: =IFERROR(VLOOKUP($G9,'Bonds Universe'!$D:$H,2,FALSE),"") -> 0.1985 | J9: 44123 | K9: =J9 -> 44123 | L9: =O9-K9 -> 106 | M9: =IFERROR(VLOOKUP($G9,'Bonds Universe'!$D:$H,3,FALSE),"") -> 45943 | N9: 44223 | O9: 44229 | P9: =IFERROR(YIELD(O9,M9,I9,Q9,100,2,0),"") -> 0.18196042 | Q9: 104.9749 | R9: 3763000 | S9: =R9*Q9/100 -> 3950205.5 | T9: =R9*I9*(L9/$N$1) -> 217520.01 | U9: =S9+T9 -> 4167725.5 | V9: =U9*0.01% -> 416.77255 | W9: =IF(F9="Buy",U9+V9,U9-V9) -> 4168142.3 | X9: 4167725.5 | Y9: =X9-U9 -> 0.0047582411 | AA9: Settled | AB9: 5.77 | AC9: =X9/AB9 -> 722309.45 | AF9: =(X9*100)/R9 -> 110.75539 | AG9: =(#REF!*100)/R9 -> #REF!
A10: 2 | B10: I.C Securities/Access Bank Ghana | C10: Mauritius | D10: SADF GHC | E10: Rasheed | F10: Buy | G10: GOG-BD 18/01/27 19.25 | I10: =IFERROR(VLOOKUP($G10,'Bonds Universe'!$D:$H,2,FALSE),"") -> 0.1925 | J10: 44221 | K10: =J10 -> 44221 | L10: =O10-K10 -> 8 | M10: =IFERROR(VLOOKUP($G10,'Bonds Universe'!$D:$H,3,FALSE),"") -> 46405 | N10: 44223 | O10: 44229 | P10: =IFERROR(YIELD(O10,M10,I10,Q10,100,2,0),"") -> 0.18943067 | Q10: 101.0386 | R10: 8216450 | S10: =R10*Q10/100 -> 8301786 | T10: =R10*I10*(L10/$N$1) -> 34761.904 | U10: =S10+T10 -> 8336548 | V10: =U10*0.01% -> 833.6548 | W10: =IF(F10="Buy",U10+V10,U10-V10) -> 8337381.6 | X10: 8336547.9 | Y10: =X10-U10 -> -0.0035461551 | AA10: Settled | AB10: 5.84 | AC10: =X10/AB10 -> 1427491.1 | AD10: 1429469.6 | AE10: =X10/AD10 -> 5.8319168 | AF10: =(X10*100)/R10 -> 101.46168 | AG10: =(#REF!*100)/R10 -> #REF!
A11: 3 | B11: I.C Securities/Access Bank Ghana | C11: Mauritius | D11: SADF GHC | E11: Rasheed | F11: Buy | G11: GOG-BD 08/11/27 20.50 | I11: =IFERROR(VLOOKUP($G11,'Bonds Universe'!$D:$H,2,FALSE),"") -> 0.205 | J11: 44151 | K11: =J11 -> 44151 | L11: =O11-K11 -> 78 | M11: =IFERROR(VLOOKUP($G11,'Bonds Universe'!$D:$H,3,FALSE),"") -> 46699 | N11: 44223 | O11: 44229 | P11: =IFERROR(YIELD(O11,M11,I11,Q11,100,2,0),"") -> 0.19095998 | Q11: 105.096 | R11: 7613850 | S11: =R11*Q11/100 -> 8001851.8 | T11: =R11*I11*(L11/$N$1) -> 334465.55 | U11: =S11+T11 -> 8336317.3 | V11: =U11*0.01% -> 833.63174 | W11: =IF(F11="Buy",U11+V11,U11-V11) -> 8337151 | X11: 8336317.4 | Y11: =X11-U11 -> 0.0004285723 | AA11: Settled | AB11: 5.77 | AC11: =X11/AB11 -> 1444769 | AE11: 5.8319168 | AF11: =(X11*100)/R11 -> 109.48886 | AG11: =(#REF!*100)/R11 -> #REF!
A12: 4 | B12: I.C Securities/Access Bank Ghana | C12: Mauritius | D12: SADF GHC | E12: Rasheed | F12: Buy | G12: GOG-BD 09/08/27 20.00 | I12: =IFERROR(VLOOKUP($G12,'Bonds Universe'!$D:$H,2,FALSE),"") -> 0.2 | J12: 44060 | K12: =J12+O1 -> 44242 | L12: =O12-K12 -> 14 | M12: =IFERROR(VLOOKUP($G12,'Bonds Universe'!$D:$H,3,FALSE),"") -> 46608 | N12: 44251 | O12: 44256 | P12: =IFERROR(YIELD(O12,M12,I12,Q12,100,2,0),"") -> 0.18693416 | Q12: 104.7305 | R12: 10000000 | S12: =R12*Q12/100 -> 10473050 | T12: =R12*I12*(L12/$N$1) -> 76923.077 | U12: =S12+T12 -> 10549973 | V12: =U12*0.01% -> 1054.9973 | W12: =IF(F12="Buy",U12+V12,U12-V12) -> 10551028 | X12: 10549973 | Y12: =X12-U12 -> 0.0030769221 | AA12: Settled | AB12: 5.77 | AC12: =X12/AB12 -> 1828418.2 | AF12: =(X12*100)/R12 -> 105.49973 | AG12: =(#REF!*100)/R12 -> #REF!
A13: 5 | B13: I.C Securities/Access Bank Ghana | C13: Mauritius | D13: SADF GHC | E13: Rasheed | F13: Buy | G13: GOG-BD 08/11/27 20.50 | I13: =IFERROR(VLOOKUP($G13,'Bonds Universe'!$D:$H,2,FALSE),"") -> 0.205 | J13: 44151 | K13: =J13+O2 -> 44151 | L13: =O13-K13 -> 105 | M13: =IFERROR(VLOOKUP($G13,'Bonds Universe'!$D:$H,3,FALSE),"") -> 46699 | N13: 44251 | O13: 44256 | P13: =IFERROR(YIELD(O13,M13,I13,Q13,100,2,0),"") -> 0.18697818 | Q13: 106.6138 | R13: 5000000 | S13: =R13*Q13/100 -> 5330690 | T13: =R13*I13*(L13/$N$1) -> 295673.08 | U13: =S13+T13 -> 5626363.1 | V13: =U13*0.01% -> 562.63631 | W13: =IF(F13="Buy",U13+V13,U13-V13) -> 5626925.7 | X13: 5626363.1 | Y13: =X13-U13 -> 0.0030769231 | AA13: Settled | AB13: 5.77 | AC13: =X13/AB13 -> 975106.25 | AF13: =(X13*100)/R13 -> 112.52726 | AG13: =(#REF!*100)/R13 -> #REF!
A14: 6 | B14: I.C Securities/Access Bank Ghana | C14: Mauritius | D14: SADF GHC | E14: Rasheed | F14: Buy | G14: GOG-BD 29/05/28 17.50 | I14: =IFERROR(VLOOKUP($G14,'Bonds Universe'!$D:$H,2,FALSE),"") -> 0.175 | J14: 43262 | K14: =J14+(2*N1)+O1 -> 44172 | L14: =O14-K14 -> 84 | M14: =IFERROR(VLOOKUP($G14,'Bonds Universe'!$D:$H,3,FALSE),"") -> 46902 | N14: 44251 | O14: 44256 | P14: =IFERROR(YIELD(O14,M14,I14,Q14,100,2,0),"") -> 0.18802067 | Q14: 94.8605 | R14: 10000000 | S14: =R14*Q14/100 -> 9486050 | T14: =R14*I14*(L14/$N$1) -> 403846.15 | U14: =S14+T14 -> 9889896.2 | V14: =U14*0.01% -> 988.98962 | W14: =IF(F14="Buy",U14+V14,U14-V14) -> 9890885.1 | X14: 9889896.2 | Y14: =X14-U14 -> -0.0038461536 | AA14: Settled | AB14: 5.77 | AC14: =X14/AB14 -> 1714020.1 | AD14: 1894249.1 | AE14: =(X14+X17)/AD14 -> 5.7269273 | AF14: =(X14*100)/R14 -> 98.898961 | AG14: =(#REF!*100)/R14 -> #REF!
A15: 7 | B15: I.C Securities/EcoBank Ghana | C15: Mauritius | D15: SADF GHC | E15: Rasheed | F15: Buy | G15: GOG-BD 09/08/27 20.00 | I15: =IFERROR(VLOOKUP($G15,'Bonds Universe'!$D:$H,2,FALSE),"") -> 0.2 | J15: 44060 | K15: =J15+$O$1 -> 44242 | L15: =O15-K15 -> 14 | M15: =IFERROR(VLOOKUP($G15,'Bonds Universe'!$D:$H,3,FALSE),"") -> 46608 | N15: 44251 | O15: 44256 | P15: =IFERROR(YIELD(O15,M15,I15,Q15,100,2,0),"") -> 0.18693416 | Q15: 104.7305 | R15: 6453350 | S15: =R15*Q15/100 -> 6758625.7 | T15: =R15*I15*(L15/$N$1) -> 49641.154 | U15: =S15+T15 -> 6808266.9 | V15: =U15*0.01% -> 680.82669 | W15: =IF(F15="Buy",U15+V15,U15-V15) -> 6808947.7 | X15: 6808266.9 | Y15: =X15-U15 -> -0.0055961544 | AA15: Settled | AB15: 5.77 | AC15: =X15/AB15 -> 1179942.3 | AE15: 5.7269273 | AF15: =(X15*100)/R15 -> 105.49973 | AG15: =(#REF!*100)/R15 -> #REF!
A16: 8 | B16: I.C Securities/EcoBank Ghana | C16: Mauritius | D16: SADF GHC | E16: Rasheed | F16: Buy | G16: GOG-BD 08/11/27 20.50 | I16: =IFERROR(VLOOKUP($G16,'Bonds Universe'!$D:$H,2,FALSE),"") -> 0.205 | J16: 44151 | K16: =J16 -> 44151 | L16: =O16-K16 -> 105 | M16: =IFERROR(VLOOKUP($G16,'Bonds Universe'!$D:$H,3,FALSE),"") -> 46699 | N16: 44251 | O16: 44256 | P16: =IFERROR(YIELD(O16,M16,I16,Q16,100,2,0),"") -> 0.18697818 | Q16: 106.6138 | R16: 8498000 | S16: =R16*Q16/100 -> 9060040.7 | T16: =R16*I16*(L16/$N$1) -> 502525.96 | U16: =S16+T16 -> 9562566.7 | V16: =U16*0.01% -> 956.25667 | W16: =IF(F16="Buy",U16+V16,U16-V16) -> 9563522.9 | X16: 9562566.7 | Y16: =X16-U16 -> -0.0055384617 | AA16: Settled | AB16: 5.77 | AC16: =X16/AB16 -> 1657290.6 | AF16: =(X16*100)/R16 -> 112.52726 | AG16: =(#REF!*100)/R16 -> #REF!
A17: 9 | B17: I.C Securities/EcoBank Ghana | C17: Mauritius | D17: SADF GHC | E17: Rasheed | F17: Buy | G17: GOG-BD 29/05/28 17.50 | I17: =IFERROR(VLOOKUP($G17,'Bonds Universe'!$D:$H,2,FALSE),"") -> 0.175 | J17: 43262 | K17: =J17+(2*N1)+O1 -> 44172 | L17: =O17-K17 -> 84 | M17: =IFERROR(VLOOKUP($G17,'Bonds Universe'!$D:$H,3,FALSE),"") -> 46902 | N17: 44251 | O17: 44256 | P17: =IFERROR(YIELD(O17,M17,I17,Q17,100,2,0),"") -> 0.18802067 | Q17: 94.8605 | R17: 969000 | S17: =R17*Q17/100 -> 919198.24 | T17: =R17*I17*(L17/$N$1) -> 39132.692 | U17: =S17+T17 -> 958330.94 | V17: =U17*0.01% -> 95.833094 | W17: =IF(F17="Buy",U17+V17,U17-V17) -> 958426.77 | X17: 958330.94 | Y17: =X17-U17 -> 0.0026923076 | AA17: Settled | AB17: 5.77 | AC17: =X17/AB17 -> 166088.55 | AF17: =(X17*100)/R17 -> 98.898962 | AG17: =(#REF!*100)/R17 -> #REF!
A18: 10 | B18: I.C Securities/Access Bank Ghana | C18: Mauritius | D18: SADF GHC | E18: Rasheed | F18: Buy | G18: GOG-BD-02/11/26 19.00 | I18: =IFERROR(VLOOKUP($G18,'Bonds Universe'!$D:$H,2,FALSE),"") -> 0.19 | J18: 42688 | K18: =J18+(4*N1) -> 44144 | L18: =O18-K18 -> 162 | M18: =IFERROR(VLOOKUP($G18,'Bonds Universe'!$D:$H,3,FALSE),"") -> 46328 | N18: 44301 | O18: 44306 | P18: =IFERROR(YIELD(O18,M18,I18,Q18,100,2,0),"") -> 0.18403003 | Q18: 101.993 | R18: 8120570 | S18: =R18*Q18/100 -> 8282413 | T18: =R18*I18*(L18/$N$1) -> 686678.97 | U18: =S18+T18 -> 8969091.9 | V18: =U18*0.01% -> 896.90919 | W18: =IF(F18="Buy",U18+V18,U18-V18) -> 8969988.8 | X18: 8969091.9 | Y18: =X18-U18 -> 0.0012186803 | AA18: Settled | AB18: 5.77 | AC18: =X18/AB18 -> 1554435.3 | AF18: =(X18*100)/R18 -> 110.44904 | AG18: =(#REF!*100)/R18 -> #REF!
A19: 11 | B19: I.C Securities/Access Bank Ghana | C19: Mauritius | D19: SADF GHC | E19: Rasheed | F19: Buy | G19: GOG-BD-02/03/26 18.30 | I19: =IFERROR(VLOOKUP($G19,'Bonds Universe'!$D:$H,2,FALSE),"") -> 0.183 | J19: 44263 | K19: =J19 -> 44263 | L19: =O19-K19 -> 43 | M19: =IFERROR(VLOOKUP($G19,'Bonds Universe'!$D:$H,3,FALSE),"") -> 46083 | N19: 44301 | O19: 44306 | P19: =IFERROR(YIELD(O19,M19,I19,Q19,100,2,0),"") -> 0.18047617 | Q19: 100.7185 | R19: 8717980 | S19: =R19*Q19/100 -> 8780618.7 | T19: =R19*I19*(L19/$N$1) -> 188466.44 | U19: =S19+T19 -> 8969085.1 | V19: =U19*0.01% -> 896.90851 | W19: =IF(F19="Buy",U19+V19,U19-V19) -> 8969982 | X19: 8969085.1 | Y19: =X19-U19 -> 0.0024362635 | AA19: Settled | AB19: 5.77 | AC19: =X19/AB19 -> 1554434.2 | AF19: =(X19*100)/R19 -> 102.88031 | AG19: =(#REF!*100)/R19 -> #REF!
A20: 12 | B20: I.C Securities/Access Bank Ghana | C20: Mauritius | D20: SADF GHC | E20: Rasheed | F20: Buy | G20: GOG-BD-13/10/25 19.85 | I20: =IFERROR(VLOOKUP($G20,'Bonds Universe'!$D:$H,2,FALSE),"") -> 0.1985 | J20: 44123 | K20: =J20+O1 -> 44305 | L20: =O20-K20 -> 1 | M20: =IFERROR(VLOOKUP($G20,'Bonds Universe'!$D:$H,3,FALSE),"") -> 45943 | N20: 44301 | O20: 44306 | P20: =IFERROR(YIELD(O20,M20,I20,Q20,100,2,0),"") -> 0.17991247 | Q20: 105.5411 | R20: 11325085 | S20: =R20*Q20/100 -> 11952619 | T20: =R20*I20*(L20/$N$1) -> 6175.9049 | U20: =S20+T20 -> 11958795 | V20: =U20*0.01% -> 1195.8795 | W20: =IF(F20="Buy",U20+V20,U20-V20) -> 11959991 | X20: 11958795 | Y20: =X20-U20 -> -0.0098045059 | AA20: Settled | AB20: 5.77 | AC20: =X20/AB20 -> 2072581.5 | AF20: =(X20*100)/R20 -> 105.59563 | AG20: =(#REF!*100)/R20 -> #REF!
A21: 13 | B21: I.C Securities/Access Bank Ghana | C21: Mauritius | D21: SADF GHC | E21: Rasheed | F21: Buy | G21: GOG-BD-13/10/25 19.85 | I21: =IFERROR(VLOOKUP($G21,'Bonds Universe'!$D:$H,2,FALSE),"") -> 0.1985 | J21: 44123 | K21: =J21+$O$1 -> 44305 | L21: =O21-K21 -> 53 | M21: =IFERROR(VLOOKUP($G21,'Bonds Universe'!$D:$H,3,FALSE),"") -> 45943 | N21: 44355 | O21: 44358 | P21: =IFERROR(YIELD(O21,M21,I21,Q21,100,2,0),"") -> 0.17994025 | Q21: 105.3376 | R21: 1433000 | S21: =R21*Q21/100 -> 1509487.8 | T21: =R21*I21*(L21/$N$1) -> 41417.243 | U21: =S21+T21 -> 1550905.1 | V21: =U21*0.01% -> 155.09051 | W21: =IF(F21="Buy",U21+V21,U21-V21) -> 1551060.1 | X21: 1550905.1 | Y21: =X21-U21 -> -0.0011318678 | AA21: Settled
A22: 14 | B22: I.C Securities/Access Bank Ghana | C22: Mauritius | D22: SADF GHC | E22: Rasheed | F22: Buy | G22: GOG-BD-02/11/26 19.00 | I22: =IFERROR(VLOOKUP($G22,'Bonds Universe'!$D:$H,2,FALSE),"") -> 0.19 | J22: 42688 | K22: =J22+(4*N1)+O1 -> 44326 | L22: =O22-K22 -> 32 | M22: =IFERROR(VLOOKUP($G22,'Bonds Universe'!$D:$H,3,FALSE),"") -> 46328 | N22: 44355 | O22: 44358 | P22: =IFERROR(YIELD(O22,M22,I22,Q22,100,2,0),"") -> 0.18395595 | Q22: 101.9431 | R22: 1496750 | S22: =R22*Q22/100 -> 1525833.3 | T22: =R22*I22*(L22/$N$1) -> 25000.659 | U22: =S22+T22 -> 1550834 | V22: =U22*0.01% -> 155.0834 | W22: =IF(F22="Buy",U22+V22,U22-V22) -> 1550989.1 | X22: 1550834 | Y22: =X22-U22 -> 0.0014093404 | AA22: Settled
A23: 15 | B23: I.C Securities/EcoBank Ghana | C23: Mauritius | D23: SADF GHC | E23: Rasheed | F23: Buy | G23: GOG-BD-18/01/27 19.25 | I23: =IFERROR(VLOOKUP($G23,'Bonds Universe'!$D:$H,2,FALSE),"") -> 0.1925 | J23: 44221 | K23: =J23 -> 44221 | L23: =O23-K23 -> 137 | M23: =IFERROR(VLOOKUP($G23,'Bonds Universe'!$D:$H,3,FALSE),"") -> 46405 | N23: 44355 | O23: 44358 | P23: =IFERROR(YIELD(O23,M23,I23,Q23,100,2,0),"") -> 0.18451082 | Q23: 102.6492 | R23: 1411000 | S23: =R23*Q23/100 -> 1448380.2 | T23: =R23*I23*(L23/$N$1) -> 102229.66 | U23: =S23+T23 -> 1550609.9 | V23: =U23*0.01% -> 155.06099 | W23: =IF(F23="Buy",U23+V23,U23-V23) -> 1550764.9 | X23: 1550609.9 | Y23: =X23-U23 -> -0.0054615382 | AA23: Settled
A24: 16 | B24: I.C Securities/Access Bank Ghana | C24: Mauritius | D24: SADF GHC | E24: Rasheed | F24: Sell | G24: GOG-BD-16/01/23 20.75 | J24: 43850 | K24: =J24+$N$1 -> 44214 | L24: =O24-K24 -> 176 | N24: 44386 | O24: 44390 | P24: =IFERROR(YIELD(O24,M24,I24,Q24,100,2,0),"") | Q24: 103.4996 | R24: 3587000 | S24: =R24*Q24/100 -> 3712530.7 | T24: =R24*I24*(L24/$N$1) -> 0 | U24: =S24+T24 -> 3712530.7 | V24: =U24*0.01% -> 371.25307 | W24: =IF(F24="Buy",U24+V24,U24-V24) -> 3712159.4 | X24: 4072413.2 | Y24: =X24-U24 -> 359882.53 | Z24: 6.04302 | AA24: Settled
A25: 17 | B25: I.C Securities/Access Bank Ghana | C25: Mauritius | D25: SADF GHC | E25: Rasheed | F25: Sell | G25: GOG-BD-06/03/23 20.75 | J25: 43899 | K25: =J25+$N$1 -> 44263 | L25: =O25-K25 -> 127 | N25: 44386 | O25: 44390 | P25: =IFERROR(YIELD(O25,M25,I25,Q25,100,2,0),"") | Q25: 103.5474 | R25: 3628000 | S25: =R25*Q25/100 -> 3756699.7 | T25: =R25*I25*(L25/$N$1) -> 0 | U25: =S25+T25 -> 3756699.7 | V25: =U25*0.01% -> 375.66997 | W25: =IF(F25="Buy",U25+V25,U25-V25) -> 3756324 | X25: 4019355.9 | Y25: =X25-U25 -> 262656.24 | Z25: 6.04302 | AA25: Settled
A26: 18 | B26: I.C Securities/Access Bank Ghana | C26: Mauritius | D26: SADF GHC | E26: Rasheed | F26: Sell | G26: GOG-BD-27/11/23 19.25 | J26: 44165 | K26: =J26+$O$1 -> 44347 | L26: =O26-K26 -> 46 | N26: 44391 | O26: 44393 | P26: =IFERROR(YIELD(O26,M26,I26,Q26,100,2,0),"") | Q26: 101.7836 | R26: 3889000 | S26: =R26*Q26/100 -> 3958364.2 | T26: =R26*I26*(L26/$N$1) -> 0 | U26: =S26+T26 -> 3958364.2 | V26: =U26*0.01% -> 395.83642 | W26: =IF(F26="Buy",U26+V26,U26-V26) -> 3957968.4 | X26: 4052971.6 | Y26: =X26-U26 -> 94607.396 | Z26: 6.138228 | AA26: Settled
A27: 19 | B27: I.C Securities/Access Bank Ghana | C27: Mauritius | D27: SADF GHC | E27: Rasheed | F27: Sell | G27: GOG-BD-02/03/26 18.30 | I27: 0.183 | J27: 44263 | K27: =J27 -> 44263 | L27: =O27-K27 -> 133 | M27: 46083 | N27: 44392 | O27: 44396 | P27: 0.18047617 | Q27: 97.0872 | R27: 8717980 | S27: =R27*Q27/100 -> 8464042.7 | T27: =R27*I27*(L27/$N$1) -> 582931.09 | U27: =S27+T27 -> 9046973.8 | V27: =U27*0.01% -> 904.69738 | W27: =IF(F27="Buy",U27+V27,U27-V27) -> 9046069.1 | X27: 9046973.8 | Y27: =X27-U27 -> 0.0056707691 | Z27: 6.138228 | AA27: Settled | AB27: 5.77
A28: 20 | B28: I.C Securities/Access Bank Ghana | C28: Mauritius | D28: SADF GHC | E28: Rasheed | F28: Sell | G28: GOG-BD-13/10/25 19.85 | I28: =IFERROR(VLOOKUP($G28,'Bonds Universe'!$D:$H,2,FALSE),"") -> 0.1985 | J28: 44123 | K28: 44305 | L28: =O28-K28 -> 94 | M28: =IFERROR(VLOOKUP($G28,'Bonds Universe'!$D:$H,3,FALSE),"") -> 45943 | N28: 44396 | O28: 44399 | P28: =IFERROR(YIELD(O28,M28,I28,Q28,100,2,0),"") -> 0.18855532 | Q28: 102.7 | R28: 10000000 | S28: =R28*Q28/100 -> 10270000 | T28: =R28*I28*(L28/$N$1) -> 512609.89 | U28: =S28+T28 -> 10782610 | V28: =U28*0.01% -> 1078.261 | W28: =IF(F28="Buy",U28+V28,U28-V28) -> 10781532 | Z28: 6.138228 | AA28: Settled | AB28: 5.77
A29: 21 | B29: I.C Securities/Access Bank Ghana | C29: Mauritius | D29: SADF GHC | E29: Rasheed | F29: Sell | G29: GOG-BD-13/10/25 19.85 | I29: =IFERROR(VLOOKUP($G29,'Bonds Universe'!$D:$H,2,FALSE),"") -> 0.1985 | J29: 44123 | K29: 44305 | L29: =O29-K29 -> 94 | M29: =IFERROR(VLOOKUP($G29,'Bonds Universe'!$D:$H,3,FALSE),"") -> 45943 | N29: 44396 | O29: 44399 | P29: =IFERROR(YIELD(O29,M29,I29,Q29,100,2,0),"") -> 0.18796694 | Q29: 102.87 | R29: 6521085 | S29: =R29*Q29/100 -> 6708240.1 | T29: =R29*I29*(L29/$N$1) -> 334277.27 | U29: =S29+T29 -> 7042517.4 | V29: =U29*0.01% -> 704.25174 | W29: =IF(F29="Buy",U29+V29,U29-V29) -> 7041813.2 | Z29: 6.138228 | AA29: Settled | AB29: 5.77
A30: 22 | B30: I.C Securities/EcoBank Ghana | C30: Mauritius | D30: SADF GHC | E30: Rasheed | F30: Sell | G30: GOG-BD 08/11/27 20.50 | I30: =IFERROR(VLOOKUP($G30,'Bonds Universe'!$D:$H,2,FALSE),"") -> 0.205 | J30: 44151 | K30: =J30+O1 -> 44333 | L30: =O30-K30 -> 70 | M30: =IFERROR(VLOOKUP($G30,'Bonds Universe'!$D:$H,3,FALSE),"") -> 46699 | N30: 44399 | O30: 44403 | P30: =IFERROR(YIELD(O30,M30,I30,Q30,100,2,0),"") -> 0.19340467 | Q30: 104 | R30: 21111850 | S30: =R30*Q30/100 -> 21956324 | T30: =R30*I30*(L30/$N$1) -> 832294.09 | U30: =S30+T30 -> 22788618 | V30: =U30*0.01% -> 2278.8618 | W30: =IF(F30="Buy",U30+V30,U30-V30) -> 22786339 | X30: 22788618 | Y30: =X30-U30 -> 0 | Z30: 6.138228 | AA30: Settled | AB30: 5.77
A31: 23 | B31: I.C Securities/Access Bank Ghana | C31: Mauritius | D31: SADF GHC | E31: Rasheed | F31: Sell | G31: GOG-BD-02/11/26 19.00 | I31: =IFERROR(VLOOKUP($G31,'Bonds Universe'!$D:$H,2,FALSE),"") -> 0.19 | J31: 42688 | K31: =J31+(4*N1)+O1 -> 44326 | L31: =O31-K31 -> 77 | M31: =IFERROR(VLOOKUP($G31,'Bonds Universe'!$D:$H,3,FALSE),"") -> 46328 | N31: 44399 | O31: 44403 | P31: =IFERROR(YIELD(O31,M31,I31,Q31,100,2,0),"") -> 0.18752655 | Q31: 100.7 | R31: 5000000 | S31: =R31*Q31/100 -> 5035000 | T31: =R31*I31*(L31/$N$1) -> 200961.54 | U31: =S31+T31 -> 5235961.5 | V31: =U31*0.01% -> 523.59615 | W31: =IF(F31="Buy",U31+V31,U31-V31) -> 5235437.9 | X31: 5235961.5 | Y31: =X31-U31 -> 0.001538462 | Z31: 6.138228 | AA31: Settled | AB31: 5.77
A32: 24 | B32: I.C Securities/Access Bank Ghana | C32: Mauritius | D32: SADF GHC | E32: Rasheed | F32: Sell | G32: GOG-BD-02/11/26 19.00 | I32: =IFERROR(VLOOKUP($G32,'Bonds Universe'!$D:$H,2,FALSE),"") -> 0.19 | J32: 42688 | K32: =J32+(4*N1)+O1 -> 44326 | L32: =O32-K32 -> 87 | M32: =IFERROR(VLOOKUP($G32,'Bonds Universe'!$D:$H,3,FALSE),"") -> 46328 | N32: 44410 | O32: 44413 | P32: =IFERROR(YIELD(O32,M32,I32,Q32,100,2,0),"") -> 0.18849616 | Q32: 100.3806 | R32: 1496750 | S32: =R32*Q32/100 -> 1502446.6 | T32: =R32*I32*(L32/$N$1) -> 67970.543 | U32: =S32+T32 -> 1570417.2 | V32: =U32*0.01% -> 157.04172 | W32: =IF(F32="Buy",U32+V32,U32-V32) -> 1570260.1 | X32: 1570417.2 | Y32: =X32-U32 -> -0.0030824179 | AA32: Settled
A33: 25 | B33: I.C Securities/EcoBank Ghana | C33: Mauritius | D33: SADF GHC | E33: Rasheed | F33: Sell | G33: GOG-BD 09/08/27 20.00 | I33: =IFERROR(VLOOKUP($G33,'Bonds Universe'!$D:$H,2,FALSE),"") -> 0.2 | J33: 44060 | K33: =J33+$N$1 -> 44424 | L33: =O33-K33 -> 25 | M33: =IFERROR(VLOOKUP($G33,'Bonds Universe'!$D:$H,3,FALSE),"") -> 46608 | N33: 44447 | O33: =N33+2 -> 44449 | P33: =IFERROR(YIELD(O33,M33,I33,Q33,100,2,0),"") -> 0.19045393 | Q33: 103.2389 | R33: 16453350 | S33: =R33*Q33/100 -> 16986258 | T33: =R33*I33*(L33/$N$1) -> 226007.55 | U33: =S33+T33 -> 17212265 | V33: =U33*0.01% -> 1721.2265 | W33: =IF(F33="Buy",U33+V33,U33-V33) -> 17210544 | X33: =W33 -> 17210544 | Y33: =X33-U33 -> -1721.2265 | AA33: Settled
A34: 26 | B34: I.C Securities/Access Bank Ghana | C34: Mauritius | D34: SADF GHC | E34: Rasheed | F34: Sell | G34: GOG-BD 18/01/27 19.25 | I34: =IFERROR(VLOOKUP($G34,'Bonds Universe'!$D:$H,2,FALSE),"") -> 0.1925 | J34: 44221 | K34: =J34+$O$1 -> 44403 | L34: =O34-K34 -> 46 | M34: =IFERROR(VLOOKUP($G34,'Bonds Universe'!$D:$H,3,FALSE),"") -> 46405 | N34: 44447 | O34: 44449 | P34: =IFERROR(YIELD(O34,M34,I34,Q34,100,2,0),"") -> 0.18947199 | Q34: 100.9031 | R34: 9627450 | S34: =R34*Q34/100 -> 9714395.5 | T34: =R34*I34*(L34/$N$1) -> 234206.24 | U34: =S34+T34 -> 9948601.7 | V34: =U34*0.01% -> 994.86017 | W34: =IF(F34="Buy",U34+V34,U34-V34) -> 9947606.9 | X34: 8336547.9 | Y34: =X34-U34 -> -1612053.8 | AA34: Settled
A35: 27 | B35: I.C Securities/Access Bank Ghana | C35: Mauritius | D35: SADF GHC | E35: Rasheed | F35: Sell | G35: GOG-BD-02/11/26 19.00 | I35: =IFERROR(VLOOKUP($G35,'Bonds Universe'!$D:$H,2,FALSE),"") -> 0.19 | J35: 42688 | K35: =J35+(4*$N$1)+$O$1 -> 44326 | L35: =O35-K35 -> 123 | M35: =IFERROR(VLOOKUP($G35,'Bonds Universe'!$D:$H,3,FALSE),"") -> 46328 | N35: 44447 | O35: 44449 | P35: =IFERROR(YIELD(O35,M35,I35,Q35,100,2,0),"") -> 0.18801366 | Q35: 100.5491 | R35: 3120570 | S35: =R35*Q35/100 -> 3137705 | T35: =R35*I35*(L35/$N$1) -> 200350.88 | U35: =S35+T35 -> 3338055.9 | V35: =U35*0.01% -> 333.80559 | W35: =IF(F35="Buy",U35+V35,U35-V35) -> 3337722.1 | X35: 1570417.2 | Y35: =X35-U35 -> -1767638.8 | AA35: Settled
A36: 28 | B36: I.C Securities/Access Bank Ghana | C36: Mauritius | D36: SADF GHC | E36: Rasheed | F36: Sell | G36: GOG-BD 29/05/28 17.50 | I36: =IFERROR(VLOOKUP($G36,'Bonds Universe'!$D:$H,2,FALSE),"") -> 0.175 | J36: 43262 | K36: =J36+(3*$N$1) -> 44354 | L36: =O36-K36 -> 98 | M36: =IFERROR(VLOOKUP($G36,'Bonds Universe'!$D:$H,3,FALSE),"") -> 46902 | N36: 44449 | O36: 44452 | P36: =IFERROR(YIELD(O36,M36,I36,Q36,100,2,0),"") -> 0.19203126 | Q36: 93.6238 | R36: 10000000 | S36: =R36*Q36/100 -> 9362380 | T36: =R36*I36*(L36/$N$1) -> 471153.85 | U36: =S36+T36 -> 9833533.8 | V36: =U36*0.01% -> 983.35338 | W36: =IF(F36="Buy",U36+V36,U36-V36) -> 9832550.5 | AA36: Settled
A37: 29 | B37: I.C Securities/Access Bank Ghana | C37: Mauritius | D37: SADF GHC | E37: Rasheed | F37: Sell | G37: GOG-BD 29/05/28 17.50 | I37: =IFERROR(VLOOKUP($G37,'Bonds Universe'!$D:$H,2,FALSE),"") -> 0.175 | J37: 43262 | K37: =J37+(3*$N$1) -> 44354 | L37: =O37-K37 -> 98 | M37: =IFERROR(VLOOKUP($G37,'Bonds Universe'!$D:$H,3,FALSE),"") -> 46902 | N37: 44449 | O37: 44452 | P37: =IFERROR(YIELD(O37,M37,I37,Q37,100,2,0),"") -> 0.19203126 | Q37: 93.6238 | R37: 969000 | S37: =R37*Q37/100 -> 907214.62 | T37: =R37*I37*(L37/$N$1) -> 45654.808 | U37: =S37+T37 -> 952869.43 | V37: =U37*0.01% -> 95.286943 | W37: =IF(F37="Buy",U37+V37,U37-V37) -> 952774.14 | AA37: Settled

Sheet NGN Domestic Trade Tracker
K1: =PRICEDISC(L85,J85,M85,100,1) -> 89.628353 | L1: 86.643625 | N1: =COUPNCD(L68,J68,2,1) -> 45042 | O1: =P68*100/O68 -> 98.777143 | P1: =P65+R65 -> 2363070714 | Q1: =P1/O65 -> 1.1815354 | R1: =P65/O65*100 -> 115.25177 | S1: 0.0005375 | T1: *100
B3: S/N | C3: CP | D3: Settlement Bank | E3: Portfolio | F3: Trader | G3: Direction | H3: Name of Asset | I3: Coupon Rate | J3: Maturity Date | K3: Trade Date | L3: Settlement Date | M3: Ytm | N3: Price | O3: Face Value | P3: Consideration | Q3: Principal | R3: Accrued Interest | S3: fees | T3: Consideration | V3: Status
B4: 1 | C4: Parthian/Sterling Bank | D4: Stanbic | E4: GIF₦ | F4: Rasheed | G4: Buy | H4: FGN 2026 Bond | I4: 0.125 | J4: 46044 | K4: 44327 | L4: 44330 | M4: =IFERROR(YIELD(L4,J4,I4,N4,100,2,1),"") -> 0.1289945 | N4: 98.58 | O4: 194000000 | P4: =IFERROR((O4*N4/100)+ACCRINT(COUPPCD(L4,J4,2,1),COUPNCD(L4,J4,2,1),L4,I4,O4,2,1),O4*N4/100) -> 1.9874796e+08 | Q4: =O4*N4/100 -> 191245200 | R4: =IFERROR(ACCRINT(COUPPCD(L4,J4,2,1),COUPNCD(L4,J4,2,0),L4,I4,O4,2,1),"") -> 7502762.4 | T4: =IFERROR(Q4+R4,Q4) -> 1.9874796e+08 | V4: Settled
B5: =B4+1 -> 2 | C5: Parthian/Sterling Bank | D5: Stanbic | E5: GIF₦ | F5: Rasheed | G5: Buy | H5: FGN 2035 Bond | I5: 0.125 | J5: 49395 | K5: 44327 | L5: 44333 | M5: =IFERROR(YIELD(L5,J5,I5,N5,100,2,1),"") -> 0.13859495 | N5: 91.68 | O5: 200000000 | P5: =IFERROR((O5*N5/100)+ACCRINT(COUPPCD(L5,J5,2,1),COUPNCD(L5,J5,2,1),L5,I5,O5,2,1),O5*N5/100) -> 1.8682467e+08 | Q5: =O5*N5/100 -> 183360000 | R5: =IFERROR(ACCRINT(COUPPCD(L5,J5,2,1),COUPNCD(L5,J5,2,0),L5,I5,O5,2,1),"") -> 3464673.9 | T5: =IFERROR(Q5+R5,Q5) -> 1.8682467e+08 | V5: Settled
B6: =B5+1 -> 3 | C6: Comercio/Coronation MB | D6: Stanbic | E6: GIF₦ | F6: Rasheed | G6: Buy | H6: FGN 2045 Bond | I6: 0.098 | J6: 53167 | K6: 44334 | L6: 44336 | M6: =YIELD(L6,J6,I6,N6,100,2,1) -> 0.1399995 | N6: 71.1 | O6: 200000000 | P6: =IFERROR((O6*N6/100)+ACCRINT(COUPPCD(L6,J6,2,1),COUPNCD(L6,J6,2,1),L6,I6,O6,2,1),O6*N6/100) -> 148480663 | Q6: =O6*N6/100 -> 142200000 | R6: =IFERROR(ACCRINT(COUPPCD(L6,J6,2,1),COUPNCD(L6,J6,2,0),L6,I6,O6,2,1),"") -> 6280663 | T6: =IFERROR(Q6+R6,Q6) -> 148480663 | V6: Settled
B7: =B6+1 -> 4 | C7: Parthian/Sterling Bank | D7: Stanbic | E7: GIF₦ | F7: Rasheed | G7: Buy | H7: FGN 2027 Bond | I7: 0.162884 | J7: 46463 | K7: 44337 | L7: 44341 | M7: =YIELD(L7,J7,I7,N7,100,2,1) -> 0.13099418 | N7: 112.64 | O7: 100000000 | P7: =IFERROR((O7*N7/100)+ACCRINT(COUPPCD(L7,J7,2,1),COUPNCD(L7,J7,2,1),L7,I7,O7,2,1),O7*N7/100) -> 115694075 | Q7: =O7*N7/100 -> 112640000 | R7: =IFERROR(ACCRINT(COUPPCD(L7,J7,2,1),COUPNCD(L7,J7,2,0),L7,I7,O7,2,1),"") -> 3054075 | T7: =IFERROR(Q7+R7,Q7) -> 115694075 | V7: Settled
B8: =B7+1 -> 5 | C8: Comercio/Coronation MB | D8: Stanbic | E8: GIF₦ | F8: Rasheed | G8: Buy | H8: FGN 2049 Bond | I8: 0.148 | J8: 54539 | K8: 44347 | L8: 44349 | M8: =YIELD(L8,J8,I8,N8,100,2,1) -> 0.13980035 | N8: 105.69 | O8: 500000000 | P8: =IFERROR((O8*N8/100)+ACCRINT(COUPPCD(L8,J8,2,1),COUPNCD(L8,J8,2,1),L8,I8,O8,2,1),O8*N8/100) -> 5.3593087e+08 | Q8: =O8*N8/100 -> 528450000 | R8: =IFERROR(ACCRINT(COUPPCD(L8,J8,2,1),COUPNCD(L8,J8,2,0),L8,I8,O8,2,1),"") -> 7480874.3 | T8: =IFERROR(Q8+R8,Q8) -> 5.3593087e+08 | V8: Settled
B9: =B8+1 -> 6 | C9: Parthian/Sterling Bank | D9: Stanbic | E9: GIF₦ | F9: Rasheed | G9: Buy | H9: FGN 2035 Bond | I9: 0.125 | J9: 49395 | K9: 44348 | L9: =K9+2 -> 44350 | M9: =IFERROR(YIELD(L9,J9,I9,N9,100,2,1),"") -> 0.13819595 | N9: 91.91 | O9: 100000000 | P9: =IFERROR((O9*N9/100)+ACCRINT(COUPPCD(L9,J9,2,1),COUPNCD(L9,J9,2,1),L9,I9,O9,2,1),O9*N9/100) -> 94219783 | Q9: =O9*N9/100 -> 91910000 | R9: =IFERROR(ACCRINT(COUPPCD(L9,J9,2,1),COUPNCD(L9,J9,2,0),L9,I9,O9,2,1),"") -> 2309782.6 | T9: =IFERROR(Q9+R9,Q9) -> 94219783 | V9: Settled
B10: =B9+1 -> 7 | C10: Parthian/Sterling Bank | D10: Stanbic | E10: GIF₦ | F10: Rasheed | G10: Buy | H10: FGN 2050 Bond | I10: 0.1298 | J10: 54874 | K10: 44348 | L10: 44350 | M10: =IFERROR(YIELD(L10,J10,I10,N10,100,2,1),"") -> 0.13919423 | N10: 93.34 | O10: 300000000 | P10: =IFERROR((O10*N10/100)+ACCRINT(COUPPCD(L10,J10,2,1),COUPNCD(L10,J10,2,1),L10,I10,O10,2,1),O10*N10/100) -> 2.8721543e+08 | Q10: =O10*N10/100 -> 280020000 | R10: =IFERROR(ACCRINT(COUPPCD(L10,J10,2,1),COUPNCD(L10,J10,2,0),L10,I10,O10,2,1),"") -> 7195434.8 | T10: =IFERROR(Q10+R10,Q10) -> 2.8721543e+08 | V10: Settled
B11: =B10+1 -> 8 | C11: Parthian/Sterling Bank | D11: Stanbic | E11: GIF₦ | F11: Rasheed | G11: Buy | H11: FGN 2050 Bond | I11: 0.1298 | J11: 54874 | K11: 44348 | L11: 44350 | M11: =IFERROR(YIELD(L11,J11,I11,N11,100,2,1),"") -> 0.13919423 | N11: 93.34 | O11: 200000000 | P11: =IFERROR((O11*N11/100)+ACCRINT(COUPPCD(L11,J11,2,1),COUPNCD(L11,J11,2,1),L11,I11,O11,2,1),O11*N11/100) -> 1.9147696e+08 | Q11: =O11*N11/100 -> 186680000 | R11: =IFERROR(ACCRINT(COUPPCD(L11,J11,2,1),COUPNCD(L11,J11,2,0),L11,I11,O11,2,1),"") -> 4796956.5 | T11: =IFERROR(Q11+R11,Q11) -> 1.9147696e+08 | V11: Settled
B12: =B11+1 -> 9 | C12: Comercio/Coronation MB | D12: Stanbic | E12: GIF₦ | F12: Rasheed | G12: Buy | H12: FGN 2049 Bond | I12: 0.148 | J12: 54539 | K12: 44344 | L12: 44351 | M12: =YIELD(L12,J12,I12,N12,100,2,1) -> 0.14030202 | N12: 105.32 | O12: 500000000 | P12: =IFERROR((O12*N12/100)+ACCRINT(COUPPCD(L12,J12,2,1),COUPNCD(L12,J12,2,1),L12,I12,O12,2,1),O12*N12/100) -> 5.3448525e+08 | Q12: =O12*N12/100 -> 526600000 | R12: =IFERROR(ACCRINT(COUPPCD(L12,J12,2,1),COUPNCD(L12,J12,2,0),L12,I12,O12,2,1),"") -> 7885245.9 | T12: =IFERROR(Q12+R12,Q12) -> 5.3448525e+08 | V12: Settled
B13: =B12+1 -> 10 | C13: Comercio/Coronation MB | D13: Stanbic | E13: GIF₦ | F13: Rasheed | G13: Buy | H13: FGN 2049 Bond | I13: 0.148 | J13: 54539 | K13: 44347 | L13: 44351 | M13: =YIELD(L13,J13,I13,N13,100,2,1) -> 0.13979804 | N13: 105.69 | O13: 300000000 | P13: =IFERROR((O13*N13/100)+ACCRINT(COUPPCD(L13,J13,2,1),COUPNCD(L13,J13,2,1),L13,I13,O13,2,1),O13*N13/100) -> 3.2180115e+08 | Q13: =O13*N13/100 -> 317070000 | R13: =IFERROR(ACCRINT(COUPPCD(L13,J13,2,1),COUPNCD(L13,J13,2,0),L13,I13,O13,2,1),"") -> 4731147.5 | T13: =IFERROR(Q13+R13,Q13) -> 3.2180115e+08 | V13: Settled
B14: =B13+1 -> 11 | C14: Comercio/Coronation MB | D14: Stanbic | E14: GIF₦ | F14: Rasheed | G14: Buy | H14: FGN 2050 Bond | I14: 0.1298 | J14: 54874 | K14: 44348 | L14: 44354 | M14: =IFERROR(YIELD(L14,J14,I14,N14,100,2,1),"") -> 0.13929889 | N14: 93.27 | O14: 300000000 | P14: =IFERROR((O14*N14/100)+ACCRINT(COUPPCD(L14,J14,2,1),COUPNCD(L14,J14,2,1),L14,I14,O14,2,1),O14*N14/100) -> 2.874287e+08 | Q14: =O14*N14/100 -> 279810000 | R14: =IFERROR(ACCRINT(COUPPCD(L14,J14,2,1),COUPNCD(L14,J14,2,0),L14,I14,O14,2,1),"") -> 7618695.7 | T14: =IFERROR(Q14+R14,Q14) -> 2.874287e+08 | V14: Settled
B15: =B14+1 -> 12 | C15: Comercio/Stanbic | D15: Stanbic | E15: GIF₦ | F15: Rasheed | G15: Buy | H15: FGN 2050 Bond | I15: 0.1298 | J15: 54874 | K15: 44371 | L15: 44372 | M15: =IFERROR(YIELD(L15,J15,I15,N15,100,2,1),"") -> 0.137 | N15: 94.807168 | O15: 1000000000 | P15: =IFERROR((O15*N15/100)+ACCRINT(COUPPCD(L15,J15,2,1),COUPNCD(L15,J15,2,1),L15,I15,O15,2,1),O15*N15/100) -> 9.7981625e+08 | Q15: =O15*N15/100 -> 9.4807168e+08 | R15: =IFERROR(ACCRINT(COUPPCD(L15,J15,2,1),COUPNCD(L15,J15,2,0),L15,I15,O15,2,1),"") -> 31744565 | T15: =IFERROR(Q15+R15,Q15) -> 9.7981625e+08 | V15: Settled
B16: =B15+1 -> 13 | C16: Stanbic IBTC | D16: Stanbic | E16: GIF₦ | F16: Rasheed | G16: Buy | H16: FGN 2050 Bond | I16: 0.1298 | J16: 54874 | K16: 44378 | L16: 44382 | M16: =IFERROR(YIELD(L16,J16,I16,N16,100,2,1),"") -> 0.13000005 | N16: 99.7995 | O16: 500000000 | P16: =IFERROR((O16*N16/100)+ACCRINT(COUPPCD(L16,J16,2,1),COUPNCD(L16,J16,2,1),L16,I16,O16,2,1),O16*N16/100) -> 5.1663337e+08 | Q16: =O16*N16/100 -> 498997500 | R16: =IFERROR(ACCRINT(COUPPCD(L16,J16,2,1),COUPNCD(L16,J16,2,0),L16,I16,O16,2,1),"") -> 17635870 | T16: =IFERROR(Q16+R16,Q16) -> 5.1663337e+08 | V16: Settled
B17: =B16+1 -> 14 | C17: Comercio/Coronation MB | D17: Stanbic | E17: GIF₦ | F17: Rasheed | G17: Buy | H17: FGN 2050 Bond | I17: 0.1298 | J17: 54874 | K17: 44379 | L17: 44383 | M17: =IFERROR(YIELD(L17,J17,I17,N17,100,2,1),"") -> 0.12999951 | N17: 99.8 | O17: 1500000000 | P17: =IFERROR((O17*N17/100)+ACCRINT(COUPPCD(L17,J17,2,1),COUPNCD(L17,J17,2,1),L17,I17,O17,2,1),O17*N17/100) -> 1550436685 | Q17: =O17*N17/100 -> 1497000000 | R17: =IFERROR(ACCRINT(COUPPCD(L17,J17,2,1),COUPNCD(L17,J17,2,0),L17,I17,O17,2,1),"") -> 53436685 | T17: =IFERROR(Q17+R17,Q17) -> 1550436685 | V17: Settled
B18: =B17+1 -> 15 | C18: Comercio/Coronation MB | D18: Stanbic | E18: GIF₦ | F18: Rasheed | G18: Sell | H18: FGN 2049 Bond | I18: 0.148 | J18: 54539 | K18: 44382 | L18: 44383 | M18: =IFERROR(YIELD(L18,J18,I18,N18,100,2,1),"") -> 0.13000446 | N18: 113.37 | O18: 700000000 | P18: =IFERROR((O18*N18/100)+ACCRINT(COUPPCD(L18,J18,2,1),COUPNCD(L18,J18,2,1),L18,I18,O18,2,1),O18*N18/100) -> 8.1368727e+08 | Q18: =O18*N18/100 -> 793590000 | R18: =IFERROR(ACCRINT(COUPPCD(L18,J18,2,1),COUPNCD(L18,J18,2,0),L18,I18,O18,2,1),"") -> 20097268 | T18: =IFERROR(Q18+R18,Q18) -> 8.1368727e+08 | V18: Settled
B19: =B18+1 -> 16 | C19: Comercio/Coronation MB | D19: Stanbic | E19: GIF₦ | F19: Rasheed | G19: Sell | H19: FGN 2035 Bond | I19: 0.125 | J19: 49395 | K19: 44382 | L19: 44383 | M19: =IFERROR(YIELD(L19,J19,I19,N19,100,2,1),"") -> 0.12949569 | N19: 97.1 | O19: 100000000 | P19: =IFERROR((O19*N19/100)+ACCRINT(COUPPCD(L19,J19,2,1),COUPNCD(L19,J19,2,1),L19,I19,O19,2,1),O19*N19/100) -> 1.0053071e+08 | Q19: =O19*N19/100 -> 97100000 | R19: =IFERROR(ACCRINT(COUPPCD(L19,J19,2,1),COUPNCD(L19,J19,2,0),L19,I19,O19,2,1),"") -> 3430706.5 | T19: =IFERROR(Q19+R19,Q19) -> 1.0053071e+08 | V19: Settled
B20: =B19+1 -> 17 | C20: Comercio/Coronation MB | D20: Stanbic | E20: GIF₦ | F20: Rasheed | G20: Sell | H20: FGN 2035 Bond | I20: 0.125 | J20: 49395 | K20: 44382 | L20: 44383 | M20: =IFERROR(YIELD(L20,J20,I20,N20,100,2,1),"") -> 0.12949569 | N20: 97.1 | O20: 200000000 | P20: =IFERROR((O20*N20/100)+ACCRINT(COUPPCD(L20,J20,2,1),COUPNCD(L20,J20,2,1),L20,I20,O20,2,1),O20*N20/100) -> 201061413 | Q20: =O20*N20/100 -> 194200000 | R20: =IFERROR(ACCRINT(COUPPCD(L20,J20,2,1),COUPNCD(L20,J20,2,0),L20,I20,O20,2,1),"") -> 6861413 | T20: =IFERROR(Q20+R20,Q20) -> 201061413 | V20: Settled
B21: =B20+1 -> 18 | C21: Stanbic IBTC | D21: Stanbic | E21: GIF₦ | F21: Rasheed | G21: Buy | H21: FGN 2050 Bond | I21: 0.1298 | J21: 54874 | K21: 44378 | L21: 44383 | M21: =IFERROR(YIELD(L21,J21,I21,N21,100,2,1),"") -> 0.13000005 | N21: 99.7996 | O21: 1200000000 | P21: =IFERROR((O21*N21/100)+ACCRINT(COUPPCD(L21,J21,2,1),COUPNCD(L21,J21,2,1),L21,I21,O21,2,1),O21*N21/100) -> 1240344548 | Q21: =O21*N21/100 -> 1197595200 | R21: =IFERROR(ACCRINT(COUPPCD(L21,J21,2,1),COUPNCD(L21,J21,2,0),L21,I21,O21,2,1),"") -> 42749348 | T21: =IFERROR(Q21+R21,Q21) -> 1240344548 | V21: Settled
